Workbook

Sheet Applications
A1: Job Title | B1: Company Name | C1: Link | D1: Location | E1: Current Status | F1: Response Status | G1: Follow Ups | H1: Date Applied | I1: Week Start (Mon) | J1: Month Start | K1: Notes | L1: Follow-Up Date
A2: AI Transformation Lead | B2: Randstand | C2: https://www.randstad.ca/jobs/ai-transformation-lead_saint-laurent_46368926/ | D2: Canada | E2: Applied | F2: No response | G2: No | H2: 46049 | I2: =IF($H2="","",$H2-WEEKDAY($H2,2)+1) -> 46048 | J2: =IF($H2="","",DATE(YEAR($H2),MONTH($H2),1)) -> 46023
A3: Incident Response Analyst | B3: Cisco | C3: https://careers.cisco.com/global/en/job/1449677/Incident-Response-Analyst | D3: Costa Rica | E3: Applied | F3: Rejected | G3: No | H3: 46027 | I3: =IF($H3="","",$H3-WEEKDAY($H3,2)+1) -> 46027 | J3: =IF($H3="","",DATE(YEAR($H3),MONTH($H3),1)) -> 46023
A4: AI Hub Campaign & Knowledge Analyst | B4: UNDP | C4: https://estm.fa.em2.oraclecloud.com/hcmUI/CandidateExperience/en/sites/CX_1/job/30896 | D4: Italy | E4: Applied | F4: No response | G4: No | H4: 46048 | I4: =IF($H4="","",$H4-WEEKDAY($H4,2)+1) -> 46048 | J4: =IF($H4="","",DATE(YEAR($H4),MONTH($H4),1)) -> 46023
A5: Application Developer/Analyst | B5: Gov't of NS | C5: https://jobs.novascotia.ca/job/HALIFAX-Application-DeveloperAnalyst-%28Computer-Services-Officer-1%28A%29-%28B%29-2%28A%29-%28C%29%29-NS-B3J-1M7/598531217/ | D5: Canada | E5: Applied | F5: No response | G5: Yes | H5: 46028 | I5: =IF($H5="","",$H5-WEEKDAY($H5,2)+1) -> 46027 | J5: =IF($H5="","",DATE(YEAR($H5),MONTH($H5),1)) -> 46023 | K5: Reached out to HR on linkedIn | L5: 46041
A6: Application Support - Java skills - Associate | B6: Hexaware | C6: https://fa-etqo-saasfaprod1.fa.ocs.oraclecloud.com/hcmUI/CandidateExperience/en/sites/CX_1/job/589735 | D6: US | E6: Applied | F6: No response | G6: No | H6: 46034 | I6: =IF($H6="","",$H6-WEEKDAY($H6,2)+1) -> 46034 | J6: =IF($H6="","",DATE(YEAR($H6),MONTH($H6),1)) -> 46023
A7: Application Support Analyst | B7: RBC | C7: https://jobs.rbc.com/ca/en/job/R-0000154313/Application-Support-Analyst | D7: Canada | E7: Applied | F7: No response | G7: No | H7: 46042 | I7: =IF($H7="","",$H7-WEEKDAY($H7,2)+1) -> 46041 | J7: =IF($H7="","",DATE(YEAR($H7),MONTH($H7),1)) -> 46023
A8: artificial intelligence (AI) designer | B8: Canadian Career Education College | C8: https://www.jobbank.gc.ca/jobsearch/jobposting/48380180 | D8: Canada | E8: Applied | F8: No response | G8: No | H8: 46044 | I8: =IF($H8="","",$H8-WEEKDAY($H8,2)+1) -> 46041 | J8: =IF($H8="","",DATE(YEAR($H8),MONTH($H8),1)) -> 46023
A9: Associate Specialist Service Operations (Service Desk) | B9: SITA | C9: https://careers-sita.icims.com/jobs/10094/associate-specialist-service-operations-%28service-desk%29/job?mode=submit_apply | D9: Canada | E9: Applied | F9: No response | G9: No | H9: 46044 | I9: =IF($H9="","",$H9-WEEKDAY($H9,2)+1) -> 46041 | J9: =IF($H9="","",DATE(YEAR($H9),MONTH($H9),1)) -> 46023
A10: Associate, UI/UX Designer | B10: BMO | C10: https://bmo.wd3.myworkdayjobs.com/en-US/External/job/Toronto-ON-CAN/Associate--UX-Lead_R250030947 | D10: Canada | E10: Applied | F10: No response | G10: No | H10: 46041 | I10: =IF($H10="","",$H10-WEEKDAY($H10,2)+1) -> 46041 | J10: =IF($H10="","",DATE(YEAR($H10),MONTH($H10),1)) -> 46023
A11: Automation Tester | B11: Expedite Talent Solutions | C11: https://www2.jobdiva.com/portal/?a=p9jdnwkqidcv6v7kl3s2jz2ipcslzc03cdv6u87hp8h64yiv0s2m7ylo90bxdjp7&SearchString=&StatesString=&source=linkedin.com&id=26462648&compid=-1#/jobs/26462648?jobtitle=Automation+Tester | D11: Canada | E11: Applied | F11: No response | G11: No | H11: 46038 | I11: =IF($H11="","",$H11-WEEKDAY($H11,2)+1) -> 46034 | J11: =IF($H11="","",DATE(YEAR($H11),MONTH($H11),1)) -> 46023
A12: Business Analyst - Intermediate | B12: Randstand | C12: https://www.randstad.ca/jobs/business-analyst-intermediate_toronto_46367020/ | D12: Canada | E12: Applied | F12: No response | G12: No | H12: 46048 | I12: =IF($H12="","",$H12-WEEKDAY($H12,2)+1) -> 46048 | J12: =IF($H12="","",DATE(YEAR($H12),MONTH($H12),1)) -> 46023
A13: Business Insights Analyst I | B13: TD | C13: https://td.wd3.myworkdayjobs.com/en-US/TD_Bank_Careers/job/Business-Insights-Analyst-I_R_1462465 | D13: Canada | E13: Applied | F13: No response | G13: No | H13: 46027 | I13: =IF($H13="","",$H13-WEEKDAY($H13,2)+1) -> 46027 | J13: =IF($H13="","",DATE(YEAR($H13),MONTH($H13),1)) -> 46023
A14: Data Services. Developer Associate (Toronto, Ottawa or Montreal) | B14: IBM | C14: https://ibmglobal.avature.net/en_US/careers/JobDetail?jobId=84810&source=WEB_Search_NA | D14: Canada | E14: Applied | F14: Rejected | G14: No | H14: 46028 | I14: =IF($H14="","",$H14-WEEKDAY($H14,2)+1) -> 46027 | J14: =IF($H14="","",DATE(YEAR($H14),MONTH($H14),1)) -> 46023
A15: Business Insights Analyst II | B15: TD | C15: https://td.wd3.myworkdayjobs.com/en-US/TD_Bank_Careers/job/Business-Insights-Analyst-II_R_1452498 | D15: Canada | E15: Applied | F15: No response | G15: No | H15: 46027 | I15: =IF($H15="","",$H15-WEEKDAY($H15,2)+1) -> 46027 | J15: =IF($H15="","",DATE(YEAR($H15),MONTH($H15),1)) -> 46023
A16: Business systems analyst | B16: Ecco Heating Products Ltd | C16: https://www.jobbank.gc.ca/jobsearch/favourites/jobposting/48157969 | D16: Canada | E16: Applied | F16: No response | G16: Yes | H16: 46050 | I16: =IF($H16="","",$H16-WEEKDAY($H16,2)+1) -> 46048 | J16: =IF($H16="","",DATE(YEAR($H16),MONTH($H16),1)) -> 46023 | K16: Sent a message to the company page on LinkedIn | L16: 46063
A17: CA-Specialist: Full-Time, Part-Time, and Part-Time Temporary role | B17: Apple | C17: https://jobs.apple.com/en-us/details/114438004/CA-Specialist-Full-Time,-Part-Time,-and-Part-Time-Temporary | D17: Canada | E17: Applied | F17: No response | G17: No | H17: 46028 | I17: =IF($H17="","",$H17-WEEKDAY($H17,2)+1) -> 46027 | J17: =IF($H17="","",DATE(YEAR($H17),MONTH($H17),1)) -> 46023
A18: Technical Support Specialist | B18: Koch | C18: https://koch.avature.net/en_US/careers/JobDetail/177798?src=LinkedIn&source=LinkedIn# | D18: US | E18: Applied | F18: Rejected | G18: No | H18: 46034 | I18: =IF($H18="","",$H18-WEEKDAY($H18,2)+1) -> 46034 | J18: =IF($H18="","",DATE(YEAR($H18),MONTH($H18),1)) -> 46023
A19: AI & Automation Data Scientist Intern | B19: IBM | C19: https://careers.ibm.com/en_US/careers/JobDetail?jobId=86185&source=External+Career+Site&tags=&user=&formValues= | D19: Canada | E19: Applied | F19: Rejected | G19: No | H19: 46037 | I19: =IF($H19="","",$H19-WEEKDAY($H19,2)+1) -> 46034 | J19: =IF($H19="","",DATE(YEAR($H19),MONTH($H19),1)) -> 46023
A20: AI Specialist – Entry Level Sales Program 2026 | B20: IBM | C20: https://careers.ibm.com/en_US/careers/JobDetail?jobId=61743&source=WEB_Leadrouting&tags=&user=&formValues= | D20: Canada | E20: Applied | F20: Rejected | G20: No | H20: 46037 | I20: =IF($H20="","",$H20-WEEKDAY($H20,2)+1) -> 46034 | J20: =IF($H20="","",DATE(YEAR($H20),MONTH($H20),1)) -> 46023
A21: Graduate Recruitment Opportunities | B21: Manulife | C21: https://careers.manulife.com/global/en/job/JR25100795/Graduate-Recruitment-Opportunities-GRO-Technology | D21: Canada | E21: Applied | F21: Rejected | G21: No | H21: 46038 | I21: =IF($H21="","",$H21-WEEKDAY($H21,2)+1) -> 46034 | J21: =IF($H21="","",DATE(YEAR($H21),MONTH($H21),1)) -> 46023
A22: Census Enumerator | B22: Gov't of Canada | C22: https://www.census.gc.ca/en/jobs?utm_source=regional-admail-wave-3&utm_medium=qrc&utm_campaign=statcan-statcan-regional-comms-recruitment-25-26&utm_content=general-recruitment-en | D22: Canada | E22: Applied | F22: No response | G22: No | H22: 46044 | I22: =IF($H22="","",$H22-WEEKDAY($H22,2)+1) -> 46041 | J22: =IF($H22="","",DATE(YEAR($H22),MONTH($H22),1)) -> 46023
A23: Automobile carrier driver | B23: East Can Transport Services Ltd. | C23: https://www.jobbank.gc.ca/jobsearch/directapply/48191896 | D23: Canada | E23: Applied | F23: Rejected | G23: No | H23: 46038 | I23: =IF($H23="","",$H23-WEEKDAY($H23,2)+1) -> 46034 | J23: =IF($H23="","",DATE(YEAR($H23),MONTH($H23),1)) -> 46023
A24: Computer technician | B24: Uniway computers | C24: https://www.jobbank.gc.ca/jobsearch/jobposting/48124798?source=searchresults | D24: Canada | E24: Applied | F24: No response | G24: No | H24: 46042 | I24: =IF($H24="","",$H24-WEEKDAY($H24,2)+1) -> 46041 | J24: =IF($H24="","",DATE(YEAR($H24),MONTH($H24),1)) -> 46023
A25: Customer Engineer | B25: Through a recruiting comopany called Hays | C25: https://www.hays.ca/job-detail/customer-engineer--oakville_1123132?q=&location=&applyId=JOB_5369759&jobSource=HaysGCJ&isSponsored=N&specialismId=&subSpecialismId=&jobName=projects%2Fmineral-balm-174308%2Ftenants%2Fab5d683d-f9a5-4b85-bfe0-eb74881e24cf%2Fjobs%2F122347838238532294 | D25: Canada | E25: Applied | F25: No response | G25: No | H25: 46048 | I25: =IF($H25="","",$H25-WEEKDAY($H25,2)+1) -> 46048 | J25: =IF($H25="","",DATE(YEAR($H25),MONTH($H25),1)) -> 46023
A26: Data Analyst | B26: CI Financial | C26: https://careers.cifinancial.com/jobs/16916545-data-analyst | D26: Canada | E26: Applied | F26: No response | G26: No | H26: 46044 | I26: =IF($H26="","",$H26-WEEKDAY($H26,2)+1) -> 46041 | J26: =IF($H26="","",DATE(YEAR($H26),MONTH($H26),1)) -> 46023
A27: Data Scientist | B27: RBC | C27: https://jobs.rbc.com/ca/en/job/R-0000152479/Data-Scientist-Halifax | D27: Canada | E27: Applied | F27: No response | G27: No | H27: 46028 | I27: =IF($H27="","",$H27-WEEKDAY($H27,2)+1) -> 46027 | J27: =IF($H27="","",DATE(YEAR($H27),MONTH($H27),1)) -> 46023
A28: Digital Data Analyst | B28: MarTech | C28: https://jobs.dayforcehcm.com/en-CA/makeawishca/CANDIDATEPORTAL/jobs/1343 | D28: Canada | E28: Applied | F28: No response | G28: No | H28: 46041 | I28: =IF($H28="","",$H28-WEEKDAY($H28,2)+1) -> 46041 | J28: =IF($H28="","",DATE(YEAR($H28),MONTH($H28),1)) -> 46023 | K28: confirmation number is 2VQ4zXJE
A29: Frontend Developer (Contract) | B29: AG Business Advisory | C29: patrick@agbusinessadvisory.com www.agbusinessadvisory.com | D29: Canada | E29: Applied | F29: No response | G29: No | H29: 46028 | I29: =IF($H29="","",$H29-WEEKDAY($H29,2)+1) -> 46027 | J29: =IF($H29="","",DATE(YEAR($H29),MONTH($H29),1)) -> 46023
A30: Software Developer, Summer 2026 (Co-op/Internship) - 12 Months | B30: BMO | C30: https://bmo.wd3.myworkdayjobs.com/en-US/External/job/Software-Developer--Summer-2026--Co-op-Internship----12-Months_R260000043-1 | D30: Canada | E30: Applied | F30: Rejected | G30: No | H30: 46041 | I30: =IF($H30="","",$H30-WEEKDAY($H30,2)+1) -> 46041 | J30: =IF($H30="","",DATE(YEAR($H30),MONTH($H30),1)) -> 46023
A31: information technology (IT) director | B31: City of Burnaby | C31: https://www.jobbank.gc.ca/jobsearch/jobposting/48407632?source=searchresults | D31: Canada | E31: Applied | F31: No response | G31: No | H31: 46051 | I31: =IF($H31="","",$H31-WEEKDAY($H31,2)+1) -> 46048 | J31: =IF($H31="","",DATE(YEAR($H31),MONTH($H31),1)) -> 46023
A32: Analyst, IT Quality Assurance | B32: CIBC | C32: https://cibc.wd3.myworkdayjobs.com/en-US/search/job/Toronto-ON/Analyst--IT-Quality-Assurance_2529251?q=%27digital+OR+technology%27&Country=a30a87ed25634629aa6c3958aa2b91ea&jobFamilyGroup=4bbe6c74e8a7011e314d36a881013310&jobFamilyGroup=4bbe6c74e8a70126f29430a881012510&jobFamilyGroup=4bbe6c74e8a7011c6e1c34a881012d10&jobFamilyGroup=4bbe6c74e8a701e2782e2da881011b10 | D32: Canada | E32: Applied | F32: Rejected | G32: No | H32: 46042 | I32: =IF($H32="","",$H32-WEEKDAY($H32,2)+1) -> 46041 | J32: =IF($H32="","",DATE(YEAR($H32),MONTH($H32),1)) -> 46023
A33: Consultant, IT Quality Assurance | B33: CIBC | C33: https://cibc.wd3.myworkdayjobs.com/en-US/search/job/Toronto-ON/Consultant--IT-Quality-Assurance_2600940?q=%27digital+OR+technology%27&Country=a30a87ed25634629aa6c3958aa2b91ea&jobFamilyGroup=4bbe6c74e8a7011e314d36a881013310&jobFamilyGroup=4bbe6c74e8a70126f29430a881012510&jobFamilyGroup=4bbe6c74e8a7011c6e1c34a881012d10&jobFamilyGroup=4bbe6c74e8a701e2782e2da881011b10 | D33: Canada | E33: Applied | F33: Rejected | G33: No | H33: 46042 | I33: =IF($H33="","",$H33-WEEKDAY($H33,2)+1) -> 46041 | J33: =IF($H33="","",DATE(YEAR($H33),MONTH($H33),1)) -> 46023
A34: information technology (IT) project manager | B34: EduCoach Consultants Inc. | C34: https://www.jobbank.gc.ca/jobsearch/favourites/jobposting/48310782 | D34: Canada | E34: Applied | F34: No response | G34: No | H34: 46042 | I34: =IF($H34="","",$H34-WEEKDAY($H34,2)+1) -> 46041 | J34: =IF($H34="","",DATE(YEAR($H34),MONTH($H34),1)) -> 46023
A35: instructional designer | B35: Team Recruitment | C35: https://www.jobbank.gc.ca/jobsearch/jobposting/48101221?source=searchresults | D35: Canada | E35: Applied | F35: No response | G35: Yes | H35: 46038 | I35: =IF($H35="","",$H35-WEEKDAY($H35,2)+1) -> 46034 | J35: =IF($H35="","",DATE(YEAR($H35),MONTH($H35),1)) -> 46023 | K35: Applied through emailing hr@teamrecruiter.com
A36: IT Help Desk Specialist | B36: SB & Company LLC | C36: https://www.paycomonline.net/v4/ats/web.php/portal/4FC6CE92B3BAE50ED87DF1496EDDBC6E/jobs/348519 | D36: US | E36: Applied | F36: No response | G36: No | H36: 46048 | I36: =IF($H36="","",$H36-WEEKDAY($H36,2)+1) -> 46048 | J36: =IF($H36="","",DATE(YEAR($H36),MONTH($H36),1)) -> 46023
A37: IT Operations Analyst III | B37: TD | C37: https://td.wd3.myworkdayjobs.com/en-US/TD_Bank_Careers/job/IT-Operations-Analyst-III_R_1450362 | D37: Canada | E37: Applied | F37: No response | G37: Yes | H37: 46027 | I37: =IF($H37="","",$H37-WEEKDAY($H37,2)+1) -> 46027 | J37: =IF($H37="","",DATE(YEAR($H37),MONTH($H37),1)) -> 46023 | K37: Sent follow up message on Jan 13 | L37: 46035
A38: IT Operations Specialist | B38: Waste Solutions Canada | C38: https://workforcenow.adp.com/mascsr/default/mdf/recruitment/recruitment.html?cid=38cbb708-0ab7-441d-b4a6-32a4800bf98c&ccId=19000101_000001&lang=en_CA&jobId=523850 | D38: Canada | E38: Applied | F38: No response | G38: No | H38: 46049 | I38: =IF($H38="","",$H38-WEEKDAY($H38,2)+1) -> 46048 | J38: =IF($H38="","",DATE(YEAR($H38),MONTH($H38),1)) -> 46023
A39: IT Technician | B39: Hitech Communications LTD | C39: Indeed | D39: Canada | E39: Applied | F39: No response | G39: No | H39: 46051 | I39: =IF($H39="","",$H39-WEEKDAY($H39,2)+1) -> 46048 | J39: =IF($H39="","",DATE(YEAR($H39),MONTH($H39),1)) -> 46023
A40: ITC - First Level Helpdesk Support | B40: City of Brandon | C40: https://jobs.dayforcehcm.com/en-US/brandon/COB/jobs/1188 | D40: Canada | E40: Applied | F40: No response | G40: No | H40: 46042 | I40: =IF($H40="","",$H40-WEEKDAY($H40,2)+1) -> 46041 | J40: =IF($H40="","",DATE(YEAR($H40),MONTH($H40),1)) -> 46023
...

Sheet Dashboard
A1: Job Application Tracker — Dashboard
A3: Total Applications | B3: =COUNTA(Applications!$H$2:$H$500) -> 75 | D3: This Week | E3: =COUNTIF(Applications!$I$2:$I$500,TODAY()-WEEKDAY(TODAY(),2)+1) -> 8 | G3: This Month | H3: =COUNTIF(Applications!$J$2:$J$500,DATE(YEAR(TODAY()),MONTH(TODAY()),1)) -> 15
A5: Counts by Current Status | D5: Weekly Applications | G5: Monthly Applications
A6: Status | B6: Count | D6: Week Start | E6: Count | G6: Month | H6: Count
A7: Applied | B7: =COUNTIF(Applications!$E$2:$E$500,A7) -> 75 | D7: 46020 | E7: 0 | G7: =Stats!D2 -> 46023 | H7: =Stats!E2 -> 60
A8: Interview | B8: =COUNTIF(Applications!$F$2:$F$500,A8) -> 2 | D8: 46027 | E8: =COUNTIF(Applications!$I$2:$I$500,D8) -> 13 | G8: =Stats!D3 -> 46054 | H8: =Stats!E3 -> 15
A9: Offer | B9: =COUNTIF(Applications!$E$2:$E$500,A9) -> 0 | D9: 46034 | E9: =COUNTIF(Applications!$I$2:$I$500,D9) -> 11 | G9: =Stats!D4 -> 46082 | H9: =Stats!E4 -> 0
A10: Rejected | B10: =B16 -> 21 | D10: 46041 | E10: =COUNTIF(Applications!$I$2:$I$500,D10) -> 18 | G10: =Stats!D5 -> 46113 | H10: =Stats!E5 -> 0
A11: No Response | B11: =COUNTIF(Applications!$F$2:$F$500,A11) -> 42 | D11: 46048 | E11: =COUNTIF(Applications!$I$2:$I$500,D11) -> 18 | G11: =Stats!D6 -> 46143 | H11: =Stats!E6 -> 0
A12: Withdrawn | B12: =COUNTIF(Applications!$F$2:$F$500,A12) -> 0 | D12: 46055 | E12: =COUNTIF(Applications!$I$2:$I$500,D12) -> 7 | G12: =Stats!D7 -> 46174 | H12: =Stats!E7 -> 0
D13: 46062 | E13: =COUNTIF(Applications!$I$2:$I$500,D13) -> 8 | G13: =Stats!D8 -> 46204 | H13: =Stats!E8 -> 0
D14: 46069 | E14: =COUNTIF(Applications!$I$2:$I$500,D14) -> 0 | G14: =Stats!D9 -> 46235 | H14: =Stats!E9 -> 0
D15: 46076 | E15: =COUNTIF(Applications!$I$2:$I$500,D15) -> 0 | G15: =Stats!D10 -> 46266 | H15: =Stats!E10 -> 0
A16: Total Rejections | B16: =COUNTIF(Applications!$F$2:$F$500,"Rejected") -> 21 | D16: 46083 | E16: =COUNTIF(Applications!$I$2:$I$500,D16) -> 0 | G16: =Stats!D11 -> 46296 | H16: =Stats!E11 -> 0
D17: 46090 | E17: =COUNTIF(Applications!$I$2:$I$500,D17) -> 0 | G17: =Stats!D12 -> 46327 | H17: =Stats!E12 -> 0
D18: 46097 | E18: =COUNTIF(Applications!$I$2:$I$500,D18) -> 0 | G18: =Stats!D13 -> 46357 | H18: =Stats!E13 -> 0
D19: 46104 | E19: =COUNTIF(Applications!$I$2:$I$500,D19) -> 0
A20: Total follow ups | B20: =COUNTIF(Applications!$G$2:$G$500,"Yes") -> 8 | D20: 46111 | E20: =COUNTIF(Applications!$I$2:$I$500,D20) -> 0
A21: Haven't followed up | B21: =COUNTIF(Applications!$G$2:$G$500,"No") -> 52 | D21: 46118 | E21: =COUNTIF(Applications!$I$2:$I$500,D21) -> 0
D22: 46125 | E22: =COUNTIF(Applications!$I$2:$I$500,D22) -> 0
D23: 46132 | E23: =COUNTIF(Applications!$I$2:$I$500,D23) -> 0
D24: 46139 | E24: =COUNTIF(Applications!$I$2:$I$500,D24) -> 0
D25: 46146 | E25: =COUNTIF(Applications!$I$2:$I$500,D25) -> 0
D26: 46153 | E26: =COUNTIF(Applications!$I$2:$I$500,D26) -> 0
D27: 46160 | E27: =COUNTIF(Applications!$I$2:$I$500,D27) -> 0
D28: 46167 | E28: =COUNTIF(Applications!$I$2:$I$500,D28) -> 0
D29: 46174 | E29: =COUNTIF(Applications!$I$2:$I$500,D29) -> 0
D30: 46181 | E30: =COUNTIF(Applications!$I$2:$I$500,D30) -> 0
D31: 46188 | E31: =COUNTIF(Applications!$I$2:$I$500,D31) -> 0
D32: 46195 | E32: =COUNTIF(Applications!$I$2:$I$500,D32) -> 0

Sheet Stats
A1: Week Start | B1: Applications | D1: Month Start | E1: Applications
A2: 46027 | B2: =COUNTIF(Applications!$I$2:$I$500,A2) -> 13 | D2: 46023 | E2: =COUNTIF(Applications!$J$2:$J$500,D2) -> 60
A3: 46034 | B3: =COUNTIF(Applications!$I$2:$I$500,A3) -> 11 | D3: 46054 | E3: =COUNTIF(Applications!$J$2:$J$500,D3) -> 15
A4: 46041 | B4: =COUNTIF(Applications!$I$2:$I$500,A4) -> 18 | D4: 46082 | E4: =COUNTIF(Applications!$J$2:$J$500,D4) -> 0
A5: 46048 | B5: =COUNTIF(Applications!$I$2:$I$500,A5) -> 18 | D5: 46113 | E5: =COUNTIF(Applications!$J$2:$J$500,D5) -> 0
A6: 46055 | B6: =COUNTIF(Applications!$I$2:$I$500,A6) -> 7 | D6: 46143 | E6: =COUNTIF(Applications!$J$2:$J$500,D6) -> 0
A7: 46062 | B7: =COUNTIF(Applications!$I$2:$I$500,A7) -> 8 | D7: 46174 | E7: =COUNTIF(Applications!$J$2:$J$500,D7) -> 0
A8: 46069 | B8: =COUNTIF(Applications!$I$2:$I$500,A8) -> 0 | D8: 46204 | E8: =COUNTIF(Applications!$J$2:$J$500,D8) -> 0
A9: 46076 | B9: =COUNTIF(Applications!$I$2:$I$500,A9) -> 0 | D9: 46235 | E9: =COUNTIF(Applications!$J$2:$J$500,D9) -> 0
A10: 46083 | B10: =COUNTIF(Applications!$I$2:$I$500,A10) -> 0 | D10: 46266 | E10: =COUNTIF(Applications!$J$2:$J$500,D10) -> 0
A11: 46090 | B11: =COUNTIF(Applications!$I$2:$I$500,A11) -> 0 | D11: 46296 | E11: =COUNTIF(Applications!$J$2:$J$500,D11) -> 0
A12: 46097 | B12: =COUNTIF(Applications!$I$2:$I$500,A12) -> 0 | D12: 46327 | E12: =COUNTIF(Applications!$J$2:$J$500,D12) -> 0
A13: 46104 | B13: =COUNTIF(Applications!$I$2:$I$500,A13) -> 0 | D13: 46357 | E13: =COUNTIF(Applications!$J$2:$J$500,D13) -> 0
A14: 46111 | B14: =COUNTIF(Applications!$I$2:$I$500,A14) -> 0
A15: 46118 | B15: =COUNTIF(Applications!$I$2:$I$500,A15) -> 0
A16: 46125 | B16: =COUNTIF(Applications!$I$2:$I$500,A16) -> 0
A17: 46132 | B17: =COUNTIF(Applications!$I$2:$I$500,A17) -> 0
A18: 46139 | B18: =COUNTIF(Applications!$I$2:$I$500,A18) -> 0
A19: 46146 | B19: =COUNTIF(Applications!$I$2:$I$500,A19) -> 0
A20: 46153 | B20: =COUNTIF(Applications!$I$2:$I$500,A20) -> 0
A21: 46160 | B21: =COUNTIF(Applications!$I$2:$I$500,A21) -> 0
A22: 46167 | B22: =COUNTIF(Applications!$I$2:$I$500,A22) -> 0
A23: 46174 | B23: =COUNTIF(Applications!$I$2:$I$500,A23) -> 0
A24: 46181 | B24: =COUNTIF(Applications!$I$2:$I$500,A24) -> 0
A25: 46188 | B25: =COUNTIF(Applications!$I$2:$I$500,A25) -> 0
A26: 46195 | B26: =COUNTIF(Applications!$I$2:$I$500,A26) -> 0

Sheet Lists
A1: Current Status List | C1: Response Status List
A2: Applied | C2: No response yet
A3: Interview | C3: Auto-reply received
A4: Offer | C4: Human reply received
A5: Rejected | C5: Interview scheduled
A6: No Response | C6: Offer received
A7: Withdrawn | C7: Rejected
